
##########################
Message: @mr.show_time said "@BOT Chat AI V.2 Hello"
-------------------
Traceback:
Traceback (most recent call last):
  File "c:\Users\SHOW_TIME\Desktop\Discord-Gemini-Chatbot\bot.py", line 122, in generate_response
    response = await model.generate_content_async(prompt_parts)
               ^^^^^^^^^^^^^^^^^^^^^^^^^^^^^^^^^^^^^^^^^^^^^^^^
  File "C:\Users\SHOW_TIME\AppData\Local\Packages\PythonSoftwareFoundation.Python.3.11_qbz5n2kfra8p0\LocalCache\local-packages\Python311\site-packages\google\generativeai\generative_models.py", line 385, in generate_content_async
    response = await self._async_client.generate_content(
               ^^^^^^^^^^^^^^^^^^^^^^^^^^^^^^^^^^^^^^^^^^
  File "C:\Users\SHOW_TIME\AppData\Local\Packages\PythonSoftwareFoundation.Python.3.11_qbz5n2kfra8p0\LocalCache\local-packages\Python311\site-packages\google\ai\generativelanguage_v1beta\services\generative_service\async_client.py", line 406, in generate_content
    response = await rpc(
               ^^^^^^^^^^
  File "C:\Users\SHOW_TIME\AppData\Local\Packages\PythonSoftwareFoundation.Python.3.11_qbz5n2kfra8p0\LocalCache\local-packages\Python311\site-packages\google\api_core\retry\retry_unary_async.py", line 230, in retry_wrapped_func
    return await retry_target(
           ^^^^^^^^^^^^^^^^^^^
  File "C:\Users\SHOW_TIME\AppData\Local\Packages\PythonSoftwareFoundation.Python.3.11_qbz5n2kfra8p0\LocalCache\local-packages\Python311\site-packages\google\api_core\retry\retry_unary_async.py", line 160, in retry_target
    _retry_error_helper(
  File "C:\Users\SHOW_TIME\AppData\Local\Packages\PythonSoftwareFoundation.Python.3.11_qbz5n2kfra8p0\LocalCache\local-packages\Python311\site-packages\google\api_core\retry\retry_base.py", line 212, in _retry_error_helper
    raise final_exc from source_exc
  File "C:\Users\SHOW_TIME\AppData\Local\Packages\PythonSoftwareFoundation.Python.3.11_qbz5n2kfra8p0\LocalCache\local-packages\Python311\site-packages\google\api_core\retry\retry_unary_async.py", line 155, in retry_target
    return await target()
           ^^^^^^^^^^^^^^
  File "C:\Users\SHOW_TIME\AppData\Local\Packages\PythonSoftwareFoundation.Python.3.11_qbz5n2kfra8p0\LocalCache\local-packages\Python311\site-packages\google\api_core\grpc_helpers_async.py", line 88, in __await__
    raise exceptions.from_grpc_error(rpc_error) from rpc_error
google.api_core.exceptions.InvalidArgument: 400 API key not valid. Please pass a valid API key. [reason: "API_KEY_INVALID"
domain: "googleapis.com"
metadata {
  key: "service"
  value: "generativelanguage.googleapis.com"
}
, locale: "en-US"
message: "API key not valid. Please pass a valid API key."
]

-------------------

##########################
Message: @mr.show_time said "@BOT Chat AI V.2  Google"
-------------------
Traceback:
Traceback (most recent call last):
  File "c:\Users\SHOW_TIME\Desktop\Discord-Gemini-Chatbot\bot.py", line 122, in generate_response
    response = await model.generate_content_async(prompt_parts)
               ^^^^^^^^^^^^^^^^^^^^^^^^^^^^^^^^^^^^^^^^^^^^^^^^
  File "C:\Users\SHOW_TIME\AppData\Local\Packages\PythonSoftwareFoundation.Python.3.11_qbz5n2kfra8p0\LocalCache\local-packages\Python311\site-packages\google\generativeai\generative_models.py", line 385, in generate_content_async
    response = await self._async_client.generate_content(
               ^^^^^^^^^^^^^^^^^^^^^^^^^^^^^^^^^^^^^^^^^^
  File "C:\Users\SHOW_TIME\AppData\Local\Packages\PythonSoftwareFoundation.Python.3.11_qbz5n2kfra8p0\LocalCache\local-packages\Python311\site-packages\google\ai\generativelanguage_v1beta\services\generative_service\async_client.py", line 406, in generate_content
    response = await rpc(
               ^^^^^^^^^^
  File "C:\Users\SHOW_TIME\AppData\Local\Packages\PythonSoftwareFoundation.Python.3.11_qbz5n2kfra8p0\LocalCache\local-packages\Python311\site-packages\google\api_core\retry\retry_unary_async.py", line 230, in retry_wrapped_func
    return await retry_target(
           ^^^^^^^^^^^^^^^^^^^
  File "C:\Users\SHOW_TIME\AppData\Local\Packages\PythonSoftwareFoundation.Python.3.11_qbz5n2kfra8p0\LocalCache\local-packages\Python311\site-packages\google\api_core\retry\retry_unary_async.py", line 160, in retry_target
    _retry_error_helper(
  File "C:\Users\SHOW_TIME\AppData\Local\Packages\PythonSoftwareFoundation.Python.3.11_qbz5n2kfra8p0\LocalCache\local-packages\Python311\site-packages\google\api_core\retry\retry_base.py", line 212, in _retry_error_helper
    raise final_exc from source_exc
  File "C:\Users\SHOW_TIME\AppData\Local\Packages\PythonSoftwareFoundation.Python.3.11_qbz5n2kfra8p0\LocalCache\local-packages\Python311\site-packages\google\api_core\retry\retry_unary_async.py", line 155, in retry_target
    return await target()
           ^^^^^^^^^^^^^^
  File "C:\Users\SHOW_TIME\AppData\Local\Packages\PythonSoftwareFoundation.Python.3.11_qbz5n2kfra8p0\LocalCache\local-packages\Python311\site-packages\google\api_core\grpc_helpers_async.py", line 88, in __await__
    raise exceptions.from_grpc_error(rpc_error) from rpc_error
google.api_core.exceptions.InvalidArgument: 400 API key not valid. Please pass a valid API key. [reason: "API_KEY_INVALID"
domain: "googleapis.com"
metadata {
  key: "service"
  value: "generativelanguage.googleapis.com"
}
, locale: "en-US"
message: "API key not valid. Please pass a valid API key."
]

-------------------

##########################
Message: @mr.show_time said "@BOT Chat AI V.2 ช่วยด้วย"
-------------------
Traceback:
Traceback (most recent call last):
  File "c:\Users\SHOW_TIME\Desktop\Discord-Gemini-Chatbot\bot.py", line 122, in generate_response
    response = await model.generate_content_async(prompt_parts)
               ^^^^^^^^^^^^^^^^^^^^^^^^^^^^^^^^^^^^^^^^^^^^^^^^
  File "C:\Users\SHOW_TIME\AppData\Local\Packages\PythonSoftwareFoundation.Python.3.11_qbz5n2kfra8p0\LocalCache\local-packages\Python311\site-packages\google\generativeai\generative_models.py", line 385, in generate_content_async
    response = await self._async_client.generate_content(
               ^^^^^^^^^^^^^^^^^^^^^^^^^^^^^^^^^^^^^^^^^^
  File "C:\Users\SHOW_TIME\AppData\Local\Packages\PythonSoftwareFoundation.Python.3.11_qbz5n2kfra8p0\LocalCache\local-packages\Python311\site-packages\google\ai\generativelanguage_v1beta\services\generative_service\async_client.py", line 406, in generate_content
    response = await rpc(
               ^^^^^^^^^^
  File "C:\Users\SHOW_TIME\AppData\Local\Packages\PythonSoftwareFoundation.Python.3.11_qbz5n2kfra8p0\LocalCache\local-packages\Python311\site-packages\google\api_core\retry\retry_unary_async.py", line 230, in retry_wrapped_func
    return await retry_target(
           ^^^^^^^^^^^^^^^^^^^
  File "C:\Users\SHOW_TIME\AppData\Local\Packages\PythonSoftwareFoundation.Python.3.11_qbz5n2kfra8p0\LocalCache\local-packages\Python311\site-packages\google\api_core\retry\retry_unary_async.py", line 160, in retry_target
    _retry_error_helper(
  File "C:\Users\SHOW_TIME\AppData\Local\Packages\PythonSoftwareFoundation.Python.3.11_qbz5n2kfra8p0\LocalCache\local-packages\Python311\site-packages\google\api_core\retry\retry_base.py", line 212, in _retry_error_helper
    raise final_exc from source_exc
  File "C:\Users\SHOW_TIME\AppData\Local\Packages\PythonSoftwareFoundation.Python.3.11_qbz5n2kfra8p0\LocalCache\local-packages\Python311\site-packages\google\api_core\retry\retry_unary_async.py", line 155, in retry_target
    return await target()
           ^^^^^^^^^^^^^^
  File "C:\Users\SHOW_TIME\AppData\Local\Packages\PythonSoftwareFoundation.Python.3.11_qbz5n2kfra8p0\LocalCache\local-packages\Python311\site-packages\google\api_core\grpc_helpers_async.py", line 88, in __await__
    raise exceptions.from_grpc_error(rpc_error) from rpc_error
google.api_core.exceptions.InvalidArgument: 400 API key not valid. Please pass a valid API key. [reason: "API_KEY_INVALID"
domain: "googleapis.com"
metadata {
  key: "service"
  value: "generativelanguage.googleapis.com"
}
, locale: "en-US"
message: "API key not valid. Please pass a valid API key."
]

-------------------

##########################
Message: @mr.show_time said "@BOT Chat AI V.2 ให้ได้ที"
-------------------
Traceback:
Traceback (most recent call last):
  File "c:\Users\SHOW_TIME\Desktop\Discord-Gemini-Chatbot\bot.py", line 122, in generate_response
    response = await model.generate_content_async(prompt_parts)
               ^^^^^^^^^^^^^^^^^^^^^^^^^^^^^^^^^^^^^^^^^^^^^^^^
  File "C:\Users\SHOW_TIME\AppData\Local\Packages\PythonSoftwareFoundation.Python.3.11_qbz5n2kfra8p0\LocalCache\local-packages\Python311\site-packages\google\generativeai\generative_models.py", line 385, in generate_content_async
    response = await self._async_client.generate_content(
               ^^^^^^^^^^^^^^^^^^^^^^^^^^^^^^^^^^^^^^^^^^
  File "C:\Users\SHOW_TIME\AppData\Local\Packages\PythonSoftwareFoundation.Python.3.11_qbz5n2kfra8p0\LocalCache\local-packages\Python311\site-packages\google\ai\generativelanguage_v1beta\services\generative_service\async_client.py", line 406, in generate_content
    response = await rpc(
               ^^^^^^^^^^
  File "C:\Users\SHOW_TIME\AppData\Local\Packages\PythonSoftwareFoundation.Python.3.11_qbz5n2kfra8p0\LocalCache\local-packages\Python311\site-packages\google\api_core\retry\retry_unary_async.py", line 230, in retry_wrapped_func
    return await retry_target(
           ^^^^^^^^^^^^^^^^^^^
  File "C:\Users\SHOW_TIME\AppData\Local\Packages\PythonSoftwareFoundation.Python.3.11_qbz5n2kfra8p0\LocalCache\local-packages\Python311\site-packages\google\api_core\retry\retry_unary_async.py", line 160, in retry_target
    _retry_error_helper(
  File "C:\Users\SHOW_TIME\AppData\Local\Packages\PythonSoftwareFoundation.Python.3.11_qbz5n2kfra8p0\LocalCache\local-packages\Python311\site-packages\google\api_core\retry\retry_base.py", line 212, in _retry_error_helper
    raise final_exc from source_exc
  File "C:\Users\SHOW_TIME\AppData\Local\Packages\PythonSoftwareFoundation.Python.3.11_qbz5n2kfra8p0\LocalCache\local-packages\Python311\site-packages\google\api_core\retry\retry_unary_async.py", line 155, in retry_target
    return await target()
           ^^^^^^^^^^^^^^
  File "C:\Users\SHOW_TIME\AppData\Local\Packages\PythonSoftwareFoundation.Python.3.11_qbz5n2kfra8p0\LocalCache\local-packages\Python311\site-packages\google\api_core\grpc_helpers_async.py", line 88, in __await__
    raise exceptions.from_grpc_error(rpc_error) from rpc_error
google.api_core.exceptions.InvalidArgument: 400 API key not valid. Please pass a valid API key. [reason: "API_KEY_INVALID"
domain: "googleapis.com"
metadata {
  key: "service"
  value: "generativelanguage.googleapis.com"
}
, locale: "en-US"
message: "API key not valid. Please pass a valid API key."
]

-------------------

##########################
Message: @mr.show_time said "@BOT Chat AI V.2  XD"
-------------------
Traceback:
Traceback (most recent call last):
  File "c:\Users\SHOW_TIME\Desktop\Discord-Gemini-Chatbot\bot.py", line 122, in generate_response
    response = await model.generate_content_async(prompt_parts)
               ^^^^^^^^^^^^^^^^^^^^^^^^^^^^^^^^^^^^^^^^^^^^^^^^
  File "C:\Users\SHOW_TIME\AppData\Local\Packages\PythonSoftwareFoundation.Python.3.11_qbz5n2kfra8p0\LocalCache\local-packages\Python311\site-packages\google\generativeai\generative_models.py", line 385, in generate_content_async
    response = await self._async_client.generate_content(
               ^^^^^^^^^^^^^^^^^^^^^^^^^^^^^^^^^^^^^^^^^^
  File "C:\Users\SHOW_TIME\AppData\Local\Packages\PythonSoftwareFoundation.Python.3.11_qbz5n2kfra8p0\LocalCache\local-packages\Python311\site-packages\google\ai\generativelanguage_v1beta\services\generative_service\async_client.py", line 406, in generate_content
    response = await rpc(
               ^^^^^^^^^^
  File "C:\Users\SHOW_TIME\AppData\Local\Packages\PythonSoftwareFoundation.Python.3.11_qbz5n2kfra8p0\LocalCache\local-packages\Python311\site-packages\google\api_core\retry\retry_unary_async.py", line 230, in retry_wrapped_func
    return await retry_target(
           ^^^^^^^^^^^^^^^^^^^
  File "C:\Users\SHOW_TIME\AppData\Local\Packages\PythonSoftwareFoundation.Python.3.11_qbz5n2kfra8p0\LocalCache\local-packages\Python311\site-packages\google\api_core\retry\retry_unary_async.py", line 160, in retry_target
    _retry_error_helper(
  File "C:\Users\SHOW_TIME\AppData\Local\Packages\PythonSoftwareFoundation.Python.3.11_qbz5n2kfra8p0\LocalCache\local-packages\Python311\site-packages\google\api_core\retry\retry_base.py", line 212, in _retry_error_helper
    raise final_exc from source_exc
  File "C:\Users\SHOW_TIME\AppData\Local\Packages\PythonSoftwareFoundation.Python.3.11_qbz5n2kfra8p0\LocalCache\local-packages\Python311\site-packages\google\api_core\retry\retry_unary_async.py", line 155, in retry_target
    return await target()
           ^^^^^^^^^^^^^^
  File "C:\Users\SHOW_TIME\AppData\Local\Packages\PythonSoftwareFoundation.Python.3.11_qbz5n2kfra8p0\LocalCache\local-packages\Python311\site-packages\google\api_core\grpc_helpers_async.py", line 88, in __await__
    raise exceptions.from_grpc_error(rpc_error) from rpc_error
google.api_core.exceptions.InvalidArgument: 400 API key not valid. Please pass a valid API key. [reason: "API_KEY_INVALID"
domain: "googleapis.com"
metadata {
  key: "service"
  value: "generativelanguage.googleapis.com"
}
, locale: "en-US"
message: "API key not valid. Please pass a valid API key."
]

-------------------

##########################
Message: @mr.show_time said "@BOT Chat AI V.2 XD"
-------------------
Traceback:
Traceback (most recent call last):
  File "c:\Users\SHOW_TIME\Desktop\Discord-Gemini-Chatbot\bot.py", line 122, in generate_response
    response = await model.generate_content_async(prompt_parts)
               ^^^^^^^^^^^^^^^^^^^^^^^^^^^^^^^^^^^^^^^^^^^^^^^^
  File "C:\Users\SHOW_TIME\AppData\Local\Packages\PythonSoftwareFoundation.Python.3.11_qbz5n2kfra8p0\LocalCache\local-packages\Python311\site-packages\google\generativeai\generative_models.py", line 385, in generate_content_async
    response = await self._async_client.generate_content(
               ^^^^^^^^^^^^^^^^^^^^^^^^^^^^^^^^^^^^^^^^^^
  File "C:\Users\SHOW_TIME\AppData\Local\Packages\PythonSoftwareFoundation.Python.3.11_qbz5n2kfra8p0\LocalCache\local-packages\Python311\site-packages\google\ai\generativelanguage_v1beta\services\generative_service\async_client.py", line 406, in generate_content
    response = await rpc(
               ^^^^^^^^^^
  File "C:\Users\SHOW_TIME\AppData\Local\Packages\PythonSoftwareFoundation.Python.3.11_qbz5n2kfra8p0\LocalCache\local-packages\Python311\site-packages\google\api_core\retry\retry_unary_async.py", line 230, in retry_wrapped_func
    return await retry_target(
           ^^^^^^^^^^^^^^^^^^^
  File "C:\Users\SHOW_TIME\AppData\Local\Packages\PythonSoftwareFoundation.Python.3.11_qbz5n2kfra8p0\LocalCache\local-packages\Python311\site-packages\google\api_core\retry\retry_unary_async.py", line 160, in retry_target
    _retry_error_helper(
  File "C:\Users\SHOW_TIME\AppData\Local\Packages\PythonSoftwareFoundation.Python.3.11_qbz5n2kfra8p0\LocalCache\local-packages\Python311\site-packages\google\api_core\retry\retry_base.py", line 212, in _retry_error_helper
    raise final_exc from source_exc
  File "C:\Users\SHOW_TIME\AppData\Local\Packages\PythonSoftwareFoundation.Python.3.11_qbz5n2kfra8p0\LocalCache\local-packages\Python311\site-packages\google\api_core\retry\retry_unary_async.py", line 155, in retry_target
    return await target()
           ^^^^^^^^^^^^^^
  File "C:\Users\SHOW_TIME\AppData\Local\Packages\PythonSoftwareFoundation.Python.3.11_qbz5n2kfra8p0\LocalCache\local-packages\Python311\site-packages\google\api_core\grpc_helpers_async.py", line 88, in __await__
    raise exceptions.from_grpc_error(rpc_error) from rpc_error
google.api_core.exceptions.InvalidArgument: 400 API key not valid. Please pass a valid API key. [reason: "API_KEY_INVALID"
domain: "googleapis.com"
metadata {
  key: "service"
  value: "generativelanguage.googleapis.com"
}
, locale: "en-US"
message: "API key not valid. Please pass a valid API key."
]

-------------------

##########################
Message: @mr.show_time said "@BOT Chat AI V.2  Hello word"
-------------------
Traceback:
Traceback (most recent call last):
  File "c:\Users\SHOW_TIME\Desktop\Discord-Gemini-Chatbot\bot.py", line 122, in generate_response
    response = await model.generate_content_async(prompt_parts)
               ^^^^^^^^^^^^^^^^^^^^^^^^^^^^^^^^^^^^^^^^^^^^^^^^
  File "C:\Users\SHOW_TIME\AppData\Local\Packages\PythonSoftwareFoundation.Python.3.11_qbz5n2kfra8p0\LocalCache\local-packages\Python311\site-packages\google\generativeai\generative_models.py", line 385, in generate_content_async
    response = await self._async_client.generate_content(
               ^^^^^^^^^^^^^^^^^^^^^^^^^^^^^^^^^^^^^^^^^^
  File "C:\Users\SHOW_TIME\AppData\Local\Packages\PythonSoftwareFoundation.Python.3.11_qbz5n2kfra8p0\LocalCache\local-packages\Python311\site-packages\google\ai\generativelanguage_v1beta\services\generative_service\async_client.py", line 406, in generate_content
    response = await rpc(
               ^^^^^^^^^^
  File "C:\Users\SHOW_TIME\AppData\Local\Packages\PythonSoftwareFoundation.Python.3.11_qbz5n2kfra8p0\LocalCache\local-packages\Python311\site-packages\google\api_core\retry\retry_unary_async.py", line 230, in retry_wrapped_func
    return await retry_target(
           ^^^^^^^^^^^^^^^^^^^
  File "C:\Users\SHOW_TIME\AppData\Local\Packages\PythonSoftwareFoundation.Python.3.11_qbz5n2kfra8p0\LocalCache\local-packages\Python311\site-packages\google\api_core\retry\retry_unary_async.py", line 160, in retry_target
    _retry_error_helper(
  File "C:\Users\SHOW_TIME\AppData\Local\Packages\PythonSoftwareFoundation.Python.3.11_qbz5n2kfra8p0\LocalCache\local-packages\Python311\site-packages\google\api_core\retry\retry_base.py", line 212, in _retry_error_helper
    raise final_exc from source_exc
  File "C:\Users\SHOW_TIME\AppData\Local\Packages\PythonSoftwareFoundation.Python.3.11_qbz5n2kfra8p0\LocalCache\local-packages\Python311\site-packages\google\api_core\retry\retry_unary_async.py", line 155, in retry_target
    return await target()
           ^^^^^^^^^^^^^^
  File "C:\Users\SHOW_TIME\AppData\Local\Packages\PythonSoftwareFoundation.Python.3.11_qbz5n2kfra8p0\LocalCache\local-packages\Python311\site-packages\google\api_core\grpc_helpers_async.py", line 88, in __await__
    raise exceptions.from_grpc_error(rpc_error) from rpc_error
google.api_core.exceptions.InvalidArgument: 400 API key not valid. Please pass a valid API key. [reason: "API_KEY_INVALID"
domain: "googleapis.com"
metadata {
  key: "service"
  value: "generativelanguage.googleapis.com"
}
, locale: "en-US"
message: "API key not valid. Please pass a valid API key."
]

-------------------
